Tkinter 例外:
Traceback (most recent call last):
  File "C:\Users\jigya.DESKTOP-UAE79A2\AppData\Local\Programs\Python\Python313\Lib\tkinter\__init__.py", line 2068, in __call__
    return self.func(*args)
           ~~~~~~~~~^^^^^^^
  File "C:\Users\jigya.DESKTOP-UAE79A2\AppData\Local\Programs\Python\Python313\Lib\tkinter\__init__.py", line 862, in callit
    func(*args)
    ~~~~^^^^^^^
  File "C:\Users\jigya.DESKTOP-UAE79A2\OneDrive\ドキュメント\Twitch配信用\v0.2.3\twitchslot\src\slot_animator.py", line 66, in finish
    on_complete()
    ~~~~~~~~~~~^^
  File "C:\Users\jigya.DESKTOP-UAE79A2\OneDrive\ドキュメント\Twitch配信用\v0.2.3\twitchslot\src\slot_animator.py", line 90, in on_complete
    username_queue.task_done()
    ~~~~~~~~~~~~~~~~~~~~~~~~^^
  File "C:\Users\jigya.DESKTOP-UAE79A2\AppData\Local\Programs\Python\Python313\Lib\queue.py", line 93, in task_done
    raise ValueError('task_done() called too many times')
ValueError: task_done() called too many times
